Workbook

Sheet main
B3: HQ - Sao Paulo, Brazil | L3: Price | M3: 13.75 | N3: USD | O3: =model!Z32/main!M3-1 -> 0.89351503 | Q3: 38.86 | R3: BRL
B4: Controlled by J&F Investimentos. | L4: Shares | M4: 2218
L5: MC | M5: =M3*M4 -> 30497.5 | N5: USD
B6: direct listing in the US incoming, definitely good | L6: Cash | M6: 4826 | N6: USD | O6: Q125
L7: Debt | M7: =795+347+19130+1398 -> 21670 | N7: USD | O7: Q125
L8: EV | M8: =M5+M7-M6 -> 47341.5 | N8: USD | O8: Q125
L10: price to earnings | M10: =M5/(model!L20*4) -> 13.688285
L11: price to sales | M11: =M5/model!L3 -> 1.5618119
L12: debt to assets | M12: =M7/model!K59 -> #DIV/0!
C13: North and Central America | D13: South america | E13: Australia | F13: Europe | G13: Others | H13: Intercompany elim | I13: Total | L13: debt to cash | M13: =M7/M6 -> 4.4902611
B14: Net revenue | C14: 45104 | D14: 21658 | E14: 6106 | F14: 5999 | G14: 376 | H14: -2061 | I14: =SUM(C14:H14) -> 77182 | L14: price to fcf | M14: =M5/model!T31 -> 11.134538
B15: Total assets | C15: 18455 | D15: 13927 | E15: 4827 | F15: 5003 | G15: 309 | H15: -1869 | I15: =SUM(C15:H15) -> 40652 | L15: price to assets | M15: =M5/model!S59 -> 0.71627366
B16: % | C16: =C14/$I$14 -> 0.58438496 | D16: =D14/$I$14 -> 0.28060947 | E16: =E14/$I$14 -> 0.07911171 | F16: =F14/$I$14 -> 0.077725376 | G16: =G14/$I$14 -> 0.0048716022
O18: Price | P18: implied # of shares | R18: USD/BRL | S18: 5.7
L19: MC | M19: 86.91 | N19: BRL | O19: 38.8 | P19: =M19/O19 -> 2.2399485 | R19: implied USD/BRL | S19: =O3/M3 -> 0.064982911
L20: MC | M20: 14.8 | N20: USD | O20: 13.78 | P20: =M20/O20 -> 1.0740203
L21: implied USD/BRL | M21: =M19/M20 -> 5.8722973
L23: spread between adr and main | M23: =M21-S18 -> 0.1722973
B27: Activities
B28: Breazil: | C28: Beef processing, Leather production and commerzialization
C29: Steel cans, plastic resin, soap, industrial waste management
C30: Commodities production/trading, energy, transportation services
C31: Distribution centers and harbors
B32: Outside brazil: | C32: Trading, beef, chicken and pork processing, fish processing\
B35: Several resent acquisitions. One of them shows entrance into the egg industry
B37: JBS tranfers account receivables to Banco Original, which is owned by the same parent
B38: It does not bear the risk of accounts receivable and gets cash in return
B39: Raises questions regarding transfer pricing issues
B43: financial statements get pretty anoying before 2021
B44: everything is in BRL from there, make sure to make correct
B45: conversions

Sheet model
A1: main | B1: in mil USD | D1: Q12023 | E1: Q22023 | F1: Q32023 | G1: Q42023 | H1: Q12024 | I1: Q22024 | J1: Q32024 | K1: Q42024 | L1: Q12025 | O1: 2020 BRL | P1: 2020 USD | Q1: 2021 | R1: 2022 | S1: 2023 | T1: =S1+1 -> 2024 | U1: =T1+1 -> 2025 | V1: =U1+1 -> 2026 | W1: =V1+1 -> 2027 | X1: =W1+1 -> 2028 | Y1: =X1+1 -> 2029 | Z1: =Y1+1 -> 2030 | AA1: =Z1+1 -> 2031 | ... BV1: =BU1+1 -> 2078
B3: Revenue | D3: 16687 | E3: 18052 | F3: 18730 | G3: 19449 | H3: 17999 | I3: 19284 | J3: 19926 | K3: 19974 | L3: 19527 | O3: 270204 | P3: =O3/$P$25 -> 48501.014 | Q3: 65043 | R3: 72619 | S3: 72918 | T3: 77183 | U3: =T3*1.05 -> 81042.15 | V3: =U3*1.05 -> 85094.258 | W3: =V3*1.05 -> 89348.97 | X3: =W3*1.05 -> 93816.419 | Y3: =X3*1.02 -> 95692.747 | Z3: =Y3*1.02 -> 97606.602 | AA3: =Z3*1.02 -> 99558.734 | AB3: =AA3*1.02 -> 101549.91 | AC3: =AB3*1.02 -> 103580.91 | AD3: =AC3*1.02 -> 105652.53 | AE3: =AD3*1.02 -> 107765.58 | AF3: =AE3*1.02 -> 109920.89 | ... BV3: =BU3*1.02 -> 252515.15
B4: COGS | D4: -15221 | E4: -16056 | F4: -16465 | G4: -17179 | H4: -15640 | I4: -16311 | J4: -16646 | K4: -16997 | L4: -16902 | O4: -224986 | P4: =O4/$P$25 -> -40384.484 | Q4: -52753 | R4: -61070 | S4: -64921 | T4: -65594
B5: Gross profit | D5: =SUM(D3:D4) -> 1466 | E5: =SUM(E3:E4) -> 1996 | F5: =SUM(F3:F4) -> 2265 | G5: =SUM(G3:G4) -> 2270 | H5: =SUM(H3:H4) -> 2359 | I5: =SUM(I3:I4) -> 2973 | J5: =SUM(J3:J4) -> 3280 | K5: =SUM(K3:K4) -> 2977 | L5: =SUM(L3:L4) -> 2625 | O5: =SUM(O3:O4) -> 45218 | P5: =O5/$P$25 -> 8116.5299 | Q5: =SUM(Q3:Q4) -> 12290 | R5: =SUM(R3:R4) -> 11549 | S5: =SUM(S3:S4) -> 7997 | T5: =SUM(T3:T4) -> 11589 | U5: =U3*U23 -> 12156.323 | V5: =V3*V23 -> 12764.139 | W5: =W3*W23 -> 13402.346 | X5: =X3*X23 -> 17825.12 | Y5: =Y3*Y23 -> 18181.622 | Z5: =Z3*Z23 -> 18545.254 | AA5: =AA3*AA23 -> 18916.16 | AB5: =AB3*AB23 -> 19294.483 | ... BV5: =BV3*BV23 -> 47977.879
B6: Selling expenses | D6: -1112 | E6: -1147 | F6: -1128 | G6: -1207 | H6: -1105 | I6: -1116 | J6: -1218 | K6: -1388 | L6: -1188 | O6: -10792 | P6: =O6/$P$25 -> -1937.1399 | Q6: -3552 | R6: -4682 | S6: -4594 | T6: -4827
B7: SG&A | D7: -514 | E7: -511 | F7: -596 | G7: -694 | H7: -528 | I7: -697 | J7: -488 | K7: -565 | L7: -556 | O7: -14481 | P7: =O7/$P$25 -> -2599.3071 | Q7: 0 | R7: -2290 | S7: -2315 | T7: -2278
B8: Other income | D8: 82 | E8: 15 | F8: 18 | G8: 33 | H8: 21 | I8: 17 | J8: 22 | K8: 24 | L8: 30 | O8: -334 | P8: =O8/$P$25 -> -59.952254 | Q8: 148 | R8: 311 | S8: 148 | T8: 84
B9: Other expenses | D9: -39 | E9: -46 | F9: -23 | G9: -14 | H9: -23 | I9: -44 | J9: -42 | K9: -80 | L9: -28 | O9: 839 | P9: =O9/$P$25 -> 150.59863 | Q9: -122 | R9: -100 | S9: -122 | T9: -189
B10: Net operating expenses | D10: =SUM(D6:D9) -> -1583 | E10: =SUM(E6:E9) -> -1689 | F10: =SUM(F6:F9) -> -1729 | G10: =SUM(G6:G9) -> -1882 | H10: =SUM(H6:H9) -> -1635 | I10: =SUM(I6:I9) -> -1840 | J10: =SUM(J6:J9) -> -1726 | K10: =SUM(K6:K9) -> -2009 | L10: =SUM(L6:L9) -> -1742 | O10: =SUM(O6:O9) -> -24768 | P10: =O10/$P$25 -> -4445.8006 | Q10: =SUM(Q6:Q9) -> -3526 | R10: =SUM(R6:R9) -> -6761 | S10: =SUM(S6:S9) -> -6883 | T10: =SUM(T6:T9) -> -7210
B11: Operating Profit | D11: -117 | E11: 308 | F11: 535 | G11: =G5+G10 -> 388 | H11: =H5+H10 -> 724 | I11: 1133 | J11: =J5+J10 -> 1554 | K11: =K5+K10 -> 968 | L11: =L5+L10 -> 883 | O11: =O5+O10 -> 20450 | P11: =O11/$P$25 -> 3670.7293 | Q11: =Q5+Q10 -> 8764 | R11: =R5+R10 -> 4788 | S11: 1084 | T11: 4377
B12: Finance income | D12: 121 | E12: 99 | F12: 123 | G12: 241 | H12: 168 | I12: 196 | J12: 153 | K12: 202 | L12: 236 | O12: 3557 | P12: =O12/$P$25 -> 638.47355 | Q12: 584 | R12: 809 | S12: 584 | T12: 719
B13: Finance expense | D13: -421 | E13: -435 | F13: -500 | G13: -581 | H13: -516 | I13: -796 | J13: -515 | K13: -562 | L13: -427 | O13: -15796 | P13: =O13/$P$25 -> -2835.3467 | Q13: -1937 | R13: -2050 | S13: -1937 | T13: -2389
B14: Net finance expense | D14: =SUM(D12:D13) -> -300 | E14: =SUM(E12:E13) -> -336 | F14: =SUM(F12:F13) -> -377 | G14: =SUM(G12:G13) -> -340 | H14: =SUM(H12:H13) -> -348 | I14: =SUM(I12:I13) -> -600 | J14: =SUM(J12:J13) -> -362 | K14: =SUM(K12:K13) -> -360 | L14: =SUM(L12:L13) -> -191 | O14: =SUM(O12:O13) -> -12239 | P14: =O14/$P$25 -> -2196.8731 | Q14: =SUM(Q12:Q13) -> -1353 | R14: =SUM(R12:R13) -> -1241 | S14: =SUM(S12:S13) -> -1353 | T14: =SUM(T12:T13) -> -1670
B15: Share of profit of equity-accounted investeesm net of tax | D15: 3 | E15: 3 | F15: 4 | G15: 0 | H15: -7 | I15: 3 | J15: 4 | K15: 3 | L15: 3 | O15: 53 | P15: =O15/$P$25 -> 9.5133816 | Q15: 10 | R15: 12 | S15: 10 | T15: 3
B16: Profit before tax | D16: =D11+D14+D15 -> -414 | E16: =E11+E14+E15 -> -25 | F16: =F11+F14+F15 -> 162 | G16: =G11+G14+G15 -> 48 | H16: =H11+H14+H15 -> 369 | I16: =I11+I14+I15 -> 536 | J16: =J11+J14+J15 -> 1196 | K16: =K11+K14+K15 -> 611 | L16: =L11+L14+L15 -> 695 | O16: =O11+O14+O15 -> 8264 | P16: =O16/$P$25 -> 1483.3695 | Q16: =Q11+Q14+Q15 -> 7421 | R16: =R11+R14+R15 -> 3559 | S16: =S11+S14+S15 -> -259 | T16: =T11+T14+T15 -> 2710
B17: Current income taxes | D17: -7 | E17: -32 | F17: -98 | G17: 68 | H17: -4 | I17: -253 | J17: -142 | K17: -471 | L17: -225 | O17: -2387 | P17: =O17/$P$25 -> -428.46117 | Q17: -69 | R17: -515 | S17: -69 | T17: -870
B18: Deferred income taxes | D18: 145 | E18: 18 | F18: 77 | G18: -43 | H18: 1 | I18: 104 | J18: -298 | K18: 320 | L18: 87 | O18: -1222 | P18: =O18/$P$25 -> -219.34627 | Q18: 197 | R18: 105 | S18: 197 | T18: 127
B19: Total income taxes | D19: =SUM(D17:D18) -> 138 | E19: =SUM(E17:E18) -> -14 | F19: =SUM(F17:F18) -> -21 | G19: =SUM(G17:G18) -> 25 | H19: =SUM(H17:H18) -> -3 | I19: =SUM(I17:I18) -> -149 | J19: =SUM(J17:J18) -> -440 | K19: =SUM(K17:K18) -> -151 | L19: =SUM(L17:L18) -> -138 | O19: =SUM(O17:O18) -> -3609 | P19: =O19/$P$25 -> -647.80743 | Q19: =SUM(Q17:Q18) -> 128 | R19: =SUM(R17:R18) -> -410 | S19: =SUM(S17:S18) -> 128 | T19: =SUM(T17:T18) -> -743
B20: Net income | D20: =D16+D19 -> -276 | E20: =E16+E19 -> -39 | F20: =F16+F19 -> 141 | G20: =G16+G19 -> 73 | H20: =H16+H19 -> 366 | I20: =I16+I19 -> 387 | J20: =J16+J19 -> 756 | K20: =K16+K19 -> 460 | L20: =L16+L19 -> 557 | O20: =O16+O19 -> 4655 | P20: =O20/$P$25 -> 835.5621 | Q20: =Q16+Q19 -> 7549 | R20: =R16+R19 -> 3149 | S20: =S16+S19 -> -131 | T20: =T16+T19 -> 1967 | U20: =U5*U21 -> 2431.2645 | V20: =V5*V21 -> 2552.8277 | W20: =W5*W21 -> 2680.4691 | X20: =X5*X21 -> 3565.0239 | Y20: =Y5*Y21 -> 3636.3244 | Z20: =Z5*Z21 -> 3709.0509 | AA20: =AA5*AA21 -> 3783.2319 | AB20: =AB5*AB21 -> 3858.8965 | ... BV20: =BV5*BV21 -> 9595.5757
B21: ni margin | P21: =P20/P5 -> 0.10294573 | Q21: =Q20/Q5 -> 0.61423922 | R21: =R20/R5 -> 0.2726643 | S21: =S20/S5 -> -0.016381143 | T21: =T20/T5 -> 0.16972992 | U21: 0.2 | V21: 0.2 | W21: 0.2 | X21: 0.2 | Y21: 0.2 | Z21: 0.2 | AA21: 0.2 | AB21: 0.2 | AC21: 0.2 | AD21: 0.2 | AE21: 0.2 | AF21: 0.2 | AG21: 0.2 | AH21: 0.2 | AI21: 0.2 | AJ21: 0.2 | AK21: 0.2 | AL21: 0.2 | AM21: 0.2 | AN21: 0.2 | AO21: 0.2 | AP21: 0.2 | AQ21: 0.2 | AR21: 0.2 | AS21: 0.2 | AT21: 0.2 | AU21: 0.2 | AV21: 0.2 | AW21: 0.2 | AX21: 0.2 | AY21: 0.2 | AZ21: 0.2 | BA21: 0.2 | BB21: 0.2 | BC21: 0.2 | BD21: 0.2 | BE21: 0.2 | BF21: 0.2 | BG21: 0.2 | BH21: 0.2 | BI21: 0.2 | BJ21: 0.2 | BK21: 0.2 | BL21: 0.2 | BM21: 0.2 | BN21: 0.2 | BO21: 0.2 | BP21: 0.2 | BQ21: 0.2 | BR21: 0.2 | BS21: 0.2 | BT21: 0.2 | BU21: 0.2 | BV21: 0.2
B22: revenue y/y | P22: -0.28 | Q22: =Q3/P3-1 -> 0.34106474 | R22: =R3/Q3-1 -> 0.11647679 | S22: =S3/R3-1 -> 0.0041173797 | T22: =T3/S3-1 -> 0.058490359
B23: gross margin | P23: =P5/P3 -> 0.16734763 | Q23: =Q5/Q3 -> 0.18895192 | R23: =R5/R3 -> 0.15903551 | S23: =S5/S3 -> 0.10967114 | T23: =T5/T3 -> 0.15014964 | U23: 0.15 | V23: 0.15 | W23: 0.15 | X23: 0.19 | Y23: 0.19 | Z23: 0.19 | AA23: 0.19 | AB23: 0.19 | AC23: 0.19 | AD23: 0.19 | AE23: 0.19 | AF23: 0.19 | AG23: 0.19 | AH23: 0.19 | AI23: 0.19 | AJ23: 0.19 | AK23: 0.19 | AL23: 0.19 | AM23: 0.19 | AN23: 0.19 | AO23: 0.19 | AP23: 0.19 | AQ23: 0.19 | AR23: 0.19 | AS23: 0.19 | AT23: 0.19 | AU23: 0.19 | AV23: 0.19 | AW23: 0.19 | AX23: 0.19 | AY23: 0.19 | AZ23: 0.19 | BA23: 0.19 | BB23: 0.19 | BC23: 0.19 | BD23: 0.19 | BE23: 0.19 | BF23: 0.19 | BG23: 0.19 | BH23: 0.19 | BI23: 0.19 | BJ23: 0.19 | BK23: 0.19 | BL23: 0.19 | BM23: 0.19 | BN23: 0.19 | BO23: 0.19 | BP23: 0.19 | BQ23: 0.19 | BR23: 0.19 | BS23: 0.19 | BT23: 0.19 | BU23: 0.19 | BV23: 0.19
P24: USD/BRL | Q24: USD/BRL
P25: 5.5711 | Q25: 5.1937
P26: BRL/USD
B27: do balance sheet | P27: =1/P25 -> 0.17949777
Y28: discount | Z28: 0.07 | AB28: demand is great, good is easy to substitute but we are talking about the leader in the space
B29: CFFO | R29: 2581 | S29: 2379 | T29: 4230 | Y29: terminal | Z29: 0.02
B30: CAPEX | R30: =2173+8 -> 2181 | S30: =1502+9 -> 1511 | T30: =1480+11 -> 1491 | Y30: ROIC | Z30: none
B31: FCF | R31: =R29-R30 -> 400 | S31: =S29-S30 -> 868 | T31: =T29-T30 -> 2739 | Y31: NPV | Z31: =NPV(Z28,T20:BV20) -> 57747.475
Y32: Share | Z32: =Z31/main!M4 -> 26.035832
B35: Assets
B36: Current Assets
B37: Cash and Cash Equivalents | S37: 4570
B38: Margin cash | S38: 132
B39: Trade accounts receivable | S39: 3391
B40: Inventories | O40: =N40+23 -> 23 | S40: 5101
B41: Biological assets | S41: 1712
B42: Recoverable taxes | S42: 919
B43: Derivative assets | S43: 88
...
